Traceback (most recent call last):
  File "/home/javi/anaconda3/lib/python3.11/site-packages/myst_nb/core/execute/inline.py", line 120, in code_cell_outputs
    self._client.execute_cell(
  File "/home/javi/anaconda3/lib/python3.11/site-packages/jupyter_core/utils/__init__.py", line 165, in wrapped
    return loop.run_until_complete(inner)
           ^^^^^^^^^^^^^^^^^^^^^^^^^^^^^^
  File "/home/javi/anaconda3/lib/python3.11/asyncio/base_events.py", line 654, in run_until_complete
    return future.result()
           ^^^^^^^^^^^^^^^
  File "/home/javi/anaconda3/lib/python3.11/site-packages/nbclient/client.py", line 1058, in async_execute_cell
    await self._check_raise_for_error(cell, cell_index, exec_reply)
  File "/home/javi/anaconda3/lib/python3.11/site-packages/nbclient/client.py", line 914, in _check_raise_for_error
    raise CellExecutionError.from_cell_and_msg(cell, exec_reply_content)
nbclient.exceptions.CellExecutionError: An error occurred while executing the following cell:
------------------
# This will fail
with open('test.txt', 'w') as f:
    for i in range(1, 5):
        f.write(i)
------------------


[0;31m---------------------------------------------------------------------------[0m
[0;31mTypeError[0m                                 Traceback (most recent call last)
Cell [0;32mIn[10], line 4[0m
[1;32m      2[0m [38;5;28;01mwith[39;00m [38;5;28mopen[39m([38;5;124m'[39m[38;5;124mtest.txt[39m[38;5;124m'[39m, [38;5;124m'[39m[38;5;124mw[39m[38;5;124m'[39m) [38;5;28;01mas[39;00m f:
[1;32m      3[0m     [38;5;28;01mfor[39;00m i [38;5;129;01min[39;00m [38;5;28mrange[39m([38;5;241m1[39m, [38;5;241m5[39m):
[0;32m----> 4[0m         f[38;5;241m.[39mwrite(i)

[0;31mTypeError[0m: write() argument must be str, not int

