Traceback (most recent call last):
  File "/home/javi/anaconda3/lib/python3.11/site-packages/myst_nb/core/execute/inline.py", line 120, in code_cell_outputs
    self._client.execute_cell(
  File "/home/javi/anaconda3/lib/python3.11/site-packages/jupyter_core/utils/__init__.py", line 165, in wrapped
    return loop.run_until_complete(inner)
           ^^^^^^^^^^^^^^^^^^^^^^^^^^^^^^
  File "/home/javi/anaconda3/lib/python3.11/asyncio/base_events.py", line 654, in run_until_complete
    return future.result()
           ^^^^^^^^^^^^^^^
  File "/home/javi/anaconda3/lib/python3.11/site-packages/nbclient/client.py", line 1058, in async_execute_cell
    await self._check_raise_for_error(cell, cell_index, exec_reply)
  File "/home/javi/anaconda3/lib/python3.11/site-packages/nbclient/client.py", line 914, in _check_raise_for_error
    raise CellExecutionError.from_cell_and_msg(cell, exec_reply_content)
nbclient.exceptions.CellExecutionError: An error occurred while executing the following cell:
------------------
string1[0] = 'Y'
------------------


[0;31m---------------------------------------------------------------------------[0m
[0;31mTypeError[0m                                 Traceback (most recent call last)
Cell [0;32mIn[37], line 1[0m
[0;32m----> 1[0m string1[[38;5;241m0[39m] [38;5;241m=[39m [38;5;124m'[39m[38;5;124mY[39m[38;5;124m'[39m

[0;31mTypeError[0m: 'str' object does not support item assignment

