Traceback (most recent call last):
  File "/home/javi/anaconda3/lib/python3.11/site-packages/myst_nb/core/execute/inline.py", line 120, in code_cell_outputs
    self._client.execute_cell(
  File "/home/javi/anaconda3/lib/python3.11/site-packages/jupyter_core/utils/__init__.py", line 165, in wrapped
    return loop.run_until_complete(inner)
           ^^^^^^^^^^^^^^^^^^^^^^^^^^^^^^
  File "/home/javi/anaconda3/lib/python3.11/asyncio/base_events.py", line 654, in run_until_complete
    return future.result()
           ^^^^^^^^^^^^^^^
  File "/home/javi/anaconda3/lib/python3.11/site-packages/nbclient/client.py", line 1058, in async_execute_cell
    await self._check_raise_for_error(cell, cell_index, exec_reply)
  File "/home/javi/anaconda3/lib/python3.11/site-packages/nbclient/client.py", line 914, in _check_raise_for_error
    raise CellExecutionError.from_cell_and_msg(cell, exec_reply_content)
nbclient.exceptions.CellExecutionError: An error occurred while executing the following cell:
------------------
# function call with only 1 of the 2 arguments
fcn_bad_args(10)
------------------


[0;31m---------------------------------------------------------------------------[0m
[0;31mTypeError[0m                                 Traceback (most recent call last)
Cell [0;32mIn[8], line 2[0m
[1;32m      1[0m [38;5;66;03m# function call with only 1 of the 2 arguments[39;00m
[0;32m----> 2[0m fcn_bad_args([38;5;241m10[39m)

[0;31mTypeError[0m: fcn_bad_args() missing 1 required positional argument: 'y'

